Workbook

Sheet 메인
B1: ’26년말 기준 재단 일자리 창출 현황
B3: 2026.09.00. 전략팀
B4: □ 누적실적 비교
B5: 구분 | E5: 조사 기업 수 | G5: 과거시점 고용인원 | I5: 최근시점 고용인원 | K5: 누적 창출 일자리 | M5: 기업당 평균 창출인원
B6: '25년 | E6: 5179 | G6: 214090 | I6: 337095 | K6: =I6-G6 -> 123005 | M6: =K6/E6 -> 23.750724
C7: 패밀리사 | E7: 436 | G7: 2578 | I7: 6487 | K7: =I7-G7 -> 3909 | M7: =K7/E7 -> 8.9655963
C8: Type2 | E8: 1120 | G8: 16563 | I8: 34365 | K8: =I8-G8 -> 17802 | M8: =K8/E8 -> 15.894643
C9: Type3 | E9: 3760 | G9: 195751 | I9: 299556 | K9: =I9-G9 -> 103805 | M9: =K9/E9 -> 27.607713
B10: '26년 상반기 | E10: =I46 -> 5327 | G10: =J46 -> 218475 | I10: =K46 -> 342146 | K10: =I10-G10 -> 123671 | M10: =K10/E10 -> 23.215881
C11: 패밀리사 | E11: =I30 -> 501 | G11: =J30 -> 3804 | I11: =K30 -> 8084 | K11: =I11-G11 -> 4280 | M11: =K11/E11 -> 8.5429142
C12: Type2 | E12: =I37 -> 1234 | G12: =J37 -> 20047 | I12: =K37 -> 38681 | K12: =I12-G12 -> 18634 | M12: =K12/E12 -> 15.100486
C13: Type3 (일자리펀드 25.12월 기준 업데이트 예정) | E13: =I43 -> 3760 | G13: =J43 -> 195751 | I13: =K43 -> 299556 | K13: =I13-G13 -> 103805 | M13: =K13/E13 -> 27.607713
B14: 25년 대비 현재 | E14: =E10-E6 -> 148 | F14: =(E10-E6)/E6 -> 0.028576945 | G14: =G10-G6 -> 4385 | H14: =(G10-G6)/G6 -> 0.02048204 | I14: =I10-I6 -> 5051 | J14: =(I10-I6)/I6 -> 0.014983907 | K14: =K10-K6 -> 666 | L14: =(K10-K6)/K6 -> 0.005414414 | M14: =M10-M6 -> -0.53484272 | N14: =(M10-M6)/M6 -> -0.022519007
B16: ※ 전년대비 조사 방법의 주요 변화
B17: 1) 패밀리사 범위에 "글로벌T1" 추가 반영
B18: 2) 패밀리사 Deactive 사유 조건을 변경
B19: - (기존) 패밀리사가 감액, 매각, 폐업하는 경우 Deactive로 분류
B20: - (변경) 패밀리사 중 "투자"에만 해당하는 기업이 감액, 매각하는 경우에만 Deactive로 분류(폐업은 계속 Deactive로 분류)
B21: 3) '25년 하반기 Type2 세컨클로징 펀드가 편입됨에 따라 이에 따른 기준시점 조건 생성
B22: - 세컨클로징 펀드의 기존 포트폴리오는 펀드 약정일(첫콜 납입 일자) 직전월을 "과거 기준시점"으로 함
B23: 3) "사업자번호 정정" 분류 삭제(사업자번호를 포함, 정정 필요힌 데이터는 원천 데이터 관리자에 공유하여 데이터 완결성에 기여)
B24: - 검색불가 기업 336개사만 별도 정리하여 명기
B26: □ '26년 상반기 집계 결과 | Q26: (개사, 명)
B27: 구분 | I27: 조사기업 수 | J27: 누적 | N27: '26년 상반기
J28: 과거 고용인원 (A) | K28: 최근 고용인원 (B) | L28: 증감수 (C=B-A) | M28: 증감율(%) (C/A) | N28: 과거 고용인원 (A) | O28: 최근 고용인원 (B) | Q28: 증감수 (C=B-A) | R28: 증감율(%) (C/A)
B29: 패밀리사 및 Type2_중복제거 (가) | I29: {=SUMPRODUCT(--((데이터시트!$B$16:$B$1584<>"")+(데이터시트!$G$16:$G$1584<>"")>0))} -> 1567 | J29: {=SUMPRODUCT(--((데이터시트!$B$16:$B$1584<>"")+(데이터시트!$G$16:$G$1584<>"")>0),데이터시트!$P$16:$P$1584)} -> 22724 | K29: {=SUMPRODUCT(--((데이터시트!$B$16:$B$1584<>"")+(데이터시트!$G$16:$G$1584<>"")>0),데이터시트!$R$16:$R$1584)} -> 42590 | L29: =IFERROR(K29-J29,"-") -> 19866 | M29: =IFERROR(L29/J29,"-") -> 0.87422989 | N29: {=SUMPRODUCT(--((데이터시트!$B$16:$B$1583<>"")+(데이터시트!$G$16:$G$1583<>"")>0),데이터시트!$Y$16:$Y$1583)} -> 41415 | O29: {=SUMPRODUCT(--(((데이터시트!$B$16:$B$1583<>"")+(데이터시트!$G$16:$G$1583<>"")>0)),데이터시트!$Z$16:$Z$1583)} -> 41835 | Q29: =IFERROR(O29-N29,"-") -> 420 | R29: =IFERROR(Q29/N29,"-") -> 0.010141253
C30: 패밀리사(Active+Deactive) | I30: =I31+I32 -> 501 | J30: =J31+J32 -> 3804 | K30: =K31+K32 -> 8084 | L30: =IFERROR(K30-J30,"-") -> 4280 | M30: =IFERROR(L30/J30,"-") -> 1.1251314 | N30: =N31+N32+N36 -> 7986 | O30: =O31+O32+O36 -> 8037 | Q30: =IFERROR(O30-N30,"-") -> 51 | R30: =IFERROR(Q30/N30,"-") -> 0.0063861758
D31: Active('26.6월말 현재 영업중인 패밀리사) | I31: =COUNTIF(데이터시트!$B$16:$B$1583,"Active")+COUNTIF(데이터시트!$B$16:$B$1583,"Active(입주)") -> 417 | J31: =SUMIF(데이터시트!$B$16:$B$1583,"Active",데이터시트!$P$16:$P$1583)+SUMIF(데이터시트!$B$16:$B$1583,"Active(입주)",데이터시트!$P$16:$P$1583) -> 3544 | K31: =SUMIF(데이터시트!$B$16:$B$1583,"Active",데이터시트!$R$16:$R$1583)+SUMIF(데이터시트!$B$16:$B$1583,"Active(입주)",데이터시트!$R$16:$R$1583) -> 7597 | L31: =IFERROR(K31-J31,"-") -> 4053 | M31: =IFERROR(L31/J31,"-") -> 1.143623 | N31: =SUMIF(데이터시트!$B$16:$B$1583,"Active",데이터시트!$Y$16:$Y$1583)+SUMIF(데이터시트!$B$16:$B$1583,"Active(입주)",데이터시트!$Y$16:$Y$1583) -> 7575 | O31: =SUMIF(데이터시트!$B$16:$B$1583,"Active",데이터시트!$Z$16:$Z$1583)+SUMIF(데이터시트!$B$16:$B$1583,"Active(입주)",데이터시트!$Z$16:$Z$1583) -> 7597 | Q31: =IFERROR(O31-N31,"-") -> 22 | R31: =IFERROR(Q31/N31,"-") -> 0.0029042904
D32: Deactive_(폐업, 감액, 매각기업) | I32: =COUNTIF(데이터시트!$B$16:$B$1583,"폐업")+COUNTIF(데이터시트!$B$16:$B$1583,"감액")+COUNTIF(데이터시트!$B$16:$B$1583,"매각") -> 84 | J32: =SUMIF(데이터시트!$B$16:$B$1583,"폐업",데이터시트!$P$16:$P$1583)+SUMIF(데이터시트!$B$16:$B$1583,"감액",데이터시트!$P$16:$P$1583)+SUMIF(데이터시트!$B$16:$B$1583,"매각",데이터시트!$P$16:$P$1583) -> 260 | K32: =SUMIF(데이터시트!$B$16:$B$1583,"폐업",데이터시트!$R$16:$R$1583)+SUMIF(데이터시트!$B$16:$B$1583,"감액",데이터시트!$R$16:$R$1583)+SUMIF(데이터시트!$B$16:$B$1583,"매각",데이터시트!$R$16:$R$1583) -> 487 | L32: =IFERROR(K32-J32,"-") -> 227 | M32: =IFERROR(L32/J32,"-") -> 0.87307692 | N32: =SUMIF(데이터시트!$B$16:$B$1583,"폐업",데이터시트!$Y$16:$Y$1583)+SUMIF(데이터시트!$B$16:$B$1583,"감액",데이터시트!$Y$16:$Y$1583)+SUMIF(데이터시트!$B$16:$B$1583,"매각",데이터시트!$Y$16:$Y$1583) -> 411 | O32: =SUMIF(데이터시트!$B$16:$B$1583,"폐업",데이터시트!$Z$16:$Z$1583)+SUMIF(데이터시트!$B$16:$B$1583,"감액",데이터시트!$Z$16:$Z$1583)+SUMIF(데이터시트!$B$16:$B$1583,"매각",데이터시트!$Z$16:$Z$1583) -> 440 | Q32: =IFERROR(O32-N32,"-") -> 29 | R32: =IFERROR(Q32/N32,"-") -> 0.070559611
D33: ㄴ Deactive 1) 폐업 | I33: =COUNTIFS(데이터시트!$B$16:$B$1583,"<>",데이터시트!$T$16:$T$1583,"<>") -> 79 | J33: =SUMIFS(데이터시트!$P$16:$P$1583,데이터시트!$B$16:$B$1583,"<>",데이터시트!$T$16:$T$1583,"<>") -> 214 | K33: =SUMIFS(데이터시트!$R$16:$R$1583,데이터시트!$B$16:$B$1583,"<>",데이터시트!$T$16:$T$1583,"<>") -> 41 | L33: =IFERROR(K33-J33,"-") -> -173 | M33: =IFERROR(L33/J33,"-") -> -0.80841121 | N33: =SUMIFS(데이터시트!$Y$16:$Y$1583,데이터시트!$B$16:$B$1583,"<>",데이터시트!$T$16:$T$1583,"<>") -> 6 | O33: =SUMIFS(데이터시트!$Z$16:$Z$1583,데이터시트!$B$16:$B$1583,"<>",데이터시트!$T$16:$T$1583,"<>") -> 0 | Q33: =IFERROR(O33-N33,"-") -> -6 | R33: =IFERROR(Q33/N33,"-") -> -1
D34: ㄴ Deactive 2) 감액_"투자"에만 해당하는 패밀리사 | I34: =COUNTIFS(데이터시트!$B$16:$B$1583,"<>",데이터시트!$D$16:$D$1583,"<>",데이터시트!$C$16:$C$1583,"",데이터시트!$E$16:$E$1583,"",데이터시트!$F$16:$F$1583,"",데이터시트!$U$16:$U$1583,"<>") -> 9 | J34: =SUMIFS(데이터시트!$P$16:$P$1583,데이터시트!$B$16:$B$1583,"<>",데이터시트!$D$16:$D$1583,"<>",데이터시트!$C$16:$C$1583,"",데이터시트!$E$16:$E$1583,"",데이터시트!$F$16:$F$1583,"",데이터시트!$U$16:$U$1583,"<>") -> 37 | K34: =SUMIFS(데이터시트!$R$16:$R$1583,데이터시트!$B$16:$B$1583,"<>",데이터시트!$D$16:$D$1583,"<>",데이터시트!$C$16:$C$1583,"",데이터시트!$E$16:$E$1583,"",데이터시트!$F$16:$F$1583,"",데이터시트!$U$16:$U$1583,"<>") -> 60 | L34: =IFERROR(K34-J34,"-") -> 23 | M34: =IFERROR(L34/J34,"-") -> 0.62162162 | N34: =SUMIFS(데이터시트!$Y$16:$Y$1583,데이터시트!$B$16:$B$1583,"<>",데이터시트!$D$16:$D$1583,"<>",데이터시트!$C$16:$C$1583,"",데이터시트!$E$16:$E$1583,"",데이터시트!$F$16:$F$1583,"",데이터시트!$U$16:$U$1583,"<>") -> 36 | O34: =SUMIFS(데이터시트!$Z$16:$Z$1583,데이터시트!$B$16:$B$1583,"<>",데이터시트!$D$16:$D$1583,"<>",데이터시트!$C$16:$C$1583,"",데이터시트!$E$16:$E$1583,"",데이터시트!$F$16:$F$1583,"",데이터시트!$U$16:$U$1583,"<>") -> 60 | Q34: =IFERROR(O34-N34,"-") -> 24 | R34: =IFERROR(Q34/N34,"-") -> 0.66666667
D35: ㄴ Deactive 3) 매각_"투자"에만 해당하는 패밀리사 | I35: =COUNTIFS(데이터시트!$B$16:$B$1583,"<>",데이터시트!$D$16:$D$1583,"<>",데이터시트!$C$16:$C$1583,"",데이터시트!$E$16:$E$1583,"",데이터시트!$F$16:$F$1583,"",데이터시트!$V$16:$V$1583,"<>") -> 12 | J35: =SUMIFS(데이터시트!$P$16:$P$1583,데이터시트!$B$16:$B$1583,"<>",데이터시트!$D$16:$D$1583,"<>",데이터시트!$C$16:$C$1583,"",데이터시트!$E$16:$E$1583,"",데이터시트!$F$16:$F$1583,"",데이터시트!$V$16:$V$1583,"<>") -> 65 | K35: =SUMIFS(데이터시트!$R$16:$R$1583,데이터시트!$B$16:$B$1583,"<>",데이터시트!$D$16:$D$1583,"<>",데이터시트!$C$16:$C$1583,"",데이터시트!$E$16:$E$1583,"",데이터시트!$F$16:$F$1583,"",데이터시트!$V$16:$V$1583,"<>") -> 487 | L35: =IFERROR(K35-J35,"-") -> 422 | M35: =IFERROR(L35/J35,"-") -> 6.4923077 | N35: =SUMIFS(데이터시트!$Y$16:$Y$1583,데이터시트!$B$16:$B$1583,"<>",데이터시트!$D$16:$D$1583,"<>",데이터시트!$C$16:$C$1583,"",데이터시트!$E$16:$E$1583,"",데이터시트!$F$16:$F$1583,"",데이터시트!$V$16:$V$1583,"<>") -> 405 | O35: =SUMIFS(데이터시트!$Z$16:$Z$1583,데이터시트!$B$16:$B$1583,"<>",데이터시트!$D$16:$D$1583,"<>",데이터시트!$C$16:$C$1583,"",데이터시트!$E$16:$E$1583,"",데이터시트!$F$16:$F$1583,"",데이터시트!$V$16:$V$1583,"<>") -> 440 | Q35: =IFERROR(O35-N35,"-") -> 35 | R35: =IFERROR(Q35/N35,"-") -> 0.086419753
D36: * 기타 데이터 제외(사업자번호 미상, 해외기업) | I36: =COUNTA('검색불가(336개사_26년 6월)'!$B$5:$B$340) -> 6 | J36: 0 | K36: 0 | L36: =IFERROR(K36-J36,"-") -> 0 | M36: =IFERROR(L36/J36,"-") -> - | N36: 0 | O36: 0 | Q36: =IFERROR(O36-N36,"-") -> 0 | R36: =IFERROR(Q36/N36,"-") -> -
C37: Type2(Active+Deactive) | I37: =I38+I39 -> 1234 | J37: =J38+J39 -> 20047 | K37: =K38+K39 -> 38681 | L37: =IFERROR(K37-J37,"-") -> 18634 | M37: =IFERROR(L37/J37,"-") -> 0.92951564 | N37: =N38+N39+N42 -> 37435 | O37: =O38+O39+O42 -> 37973 | Q37: =IFERROR(O37-N37,"-") -> 538 | R37: =IFERROR(Q37/N37,"-") -> 0.014371577
D38: Active(운용중인 펀드의 영업중인 피투자사) | I38: =COUNTIF(데이터시트!$G$16:$G$1583,"Active") -> 1094 | J38: =SUMIF(데이터시트!$G$16:$G$1583,"Active",데이터시트!$P$16:$P$1583) -> 18747 | K38: =SUMIF(데이터시트!$G$16:$G$1583,"Active",데이터시트!$R$16:$R$1583) -> 37848 | L38: =IFERROR(K38-J38,"-") -> 19101 | M38: =IFERROR(L38/J38,"-") -> 1.018883 | N38: =SUMIF(데이터시트!$G$16:$G$1583,"Active",데이터시트!$Y$16:$Y$1583) -> 37242 | O38: =SUMIF(데이터시트!$G$16:$G$1583,"Active",데이터시트!$Z$16:$Z$1583) -> 37848 | Q38: =IFERROR(O38-N38,"-") -> 606 | R38: =IFERROR(Q38/N38,"-") -> 0.016271951
D39: Deactive_(폐업, 청산/매각펀드 포트폴리오 기업) | I39: =COUNTIF(데이터시트!$G$16:$G$1583,"폐업")+COUNTIF(데이터시트!$G$16:$G$1583,"청산/매각") -> 140 | J39: =SUMIF(데이터시트!$G$16:$G$1583,"폐업",데이터시트!$P$16:$P$1583)+SUMIF(데이터시트!$G$16:$G$1583,"청산/매각",데이터시트!$P$16:$P$1583) -> 1300 | K39: =SUMIF(데이터시트!$G$16:$G$1583,"폐업",데이터시트!$R$16:$R$1583)+SUMIF(데이터시트!$G$16:$G$1583,"청산/매각",데이터시트!$R$16:$R$1583) -> 833 | L39: =IFERROR(K39-J39,"-") -> -467 | M39: =IFERROR(L39/J39,"-") -> -0.35923077 | N39: =SUMIF(데이터시트!$G$16:$G$1583,"폐업",데이터시트!$Y$16:$Y$1583)+SUMIF(데이터시트!$G$16:$G$1583,"청산/매각",데이터시트!$Y$16:$Y$1583) -> 193 | O39: =SUMIF(데이터시트!$G$16:$G$1583,"폐업",데이터시트!$Z$16:$Z$1583)+SUMIF(데이터시트!$G$16:$G$1583,"청산/매각",데이터시트!$Z$16:$Z$1583) -> 125 | Q39: =IFERROR(O39-N39,"-") -> -68 | R39: =IFERROR(Q39/N39,"-") -> -0.35233161
D40: ㄴ Deactive 1) 폐업 | I40: =COUNTIFS(데이터시트!$G$16:$G$1583,"<>",데이터시트!$T$16:$T$1583,"<>") -> 114 | J40: =SUMIFS(데이터시트!$P$16:$P$1583,데이터시트!$G$16:$G$1583,"<>",데이터시트!$T$16:$T$1583,"<>") -> 1081 | K40: =SUMIFS(데이터시트!$R$16:$R$1583,데이터시트!$G$16:$G$1583,"<>",데이터시트!$T$16:$T$1583,"<>") -> 24 | L40: =IFERROR(K40-J40,"-") -> -1057 | M40: =IFERROR(L40/J40,"-") -> -0.97779833 | N40: =SUMIFS(데이터시트!$Y$16:$Y$1583,데이터시트!$G$16:$G$1583,"<>",데이터시트!$T$16:$T$1583,"<>") -> 53 | O40: =SUMIFS(데이터시트!$Z$16:$Z$1583,데이터시트!$G$16:$G$1583,"<>",데이터시트!$T$16:$T$1583,"<>") -> 0 | Q40: =IFERROR(O40-N40,"-") -> -53 | R40: =IFERROR(Q40/N40,"-") -> -1
D41: ㄴ Deactive 2) 청산/매각 펀드 포트폴리오 | I41: =COUNTIFS(데이터시트!$G$16:$G$1583,"<>",데이터시트!$W$16:$W$1583,"<>") -> 31 | J41: =SUMIFS(데이터시트!$P$16:$P$1583,데이터시트!$G$16:$G$1583,"<>",데이터시트!$W$16:$W$1583,"<>") -> 249 | K41: =SUMIFS(데이터시트!$R$16:$R$1583,데이터시트!$G$16:$G$1583,"<>",데이터시트!$W$16:$W$1583,"<>") -> 833 | L41: =IFERROR(K41-J41,"-") -> 584 | M41: =IFERROR(L41/J41,"-") -> 2.3453815 | N41: =SUMIFS(데이터시트!$Y$16:$Y$1583,데이터시트!$G$16:$G$1583,"<>",데이터시트!$W$16:$W$1583,"<>") -> 140 | O41: =SUMIFS(데이터시트!$Z$16:$Z$1583,데이터시트!$G$16:$G$1583,"<>",데이터시트!$W$16:$W$1583,"<>") -> 125 | Q41: =IFERROR(O41-N41,"-") -> -15 | R41: =IFERROR(Q41/N41,"-") -> -0.10714286
D42: * 기타 데이터 제외(사업자번호 미상, 해외가업, 특수목적법인) | I42: =COUNTA('검색불가(336개사_26년 6월)'!$G$5:$G$340) -> 330 | J42: 0 | K42: 0 | L42: =IFERROR(K42-J42,"-") -> 0 | M42: =IFERROR(L42/J42,"-") -> - | N42: 0 | O42: 0 | Q42: =IFERROR(O42-N42,"-") -> 0 | R42: =IFERROR(Q42/N42,"-") -> -
B43: Type3* (나) | I43: =SUM(I44:I45) -> 3760 | J43: =SUM(J44:J45) -> 195751 | K43: =SUM(K44:K45) -> 299556 | L43: =IFERROR(K43-J43,"-") -> 103805 | M43: =IFERROR(L43/J43,"-") -> 0.53029103
...

Sheet 데이터시트
A1: 누적 일자리 창출 현황 ('26.6월 기준)
A2: ㅇ 조사대상 : (패밀리사) ‘26년 6월말까지의 배치·입주·투자·글로벌 T1 기업 (파트너트랙 입주 제외) / (Type2) ‘25년 말까지의 Type2 출자펀드 투자 기업 | M2: [데이터 출처]
A3: ㅇ 패밀리사 또는 Type2 투자기업 편입 직전월을 "과거 기준시점"으로 함 | M3: 패밀리사 정보 | N3: [사업실]디캠프 전체기업정보
A4: - 패밀리사이면서 Type2 투자기업인 경우 둘 중 편입이 빠른 시점의 고용인원 수만 집계 | M4: Type2 투자기업 정보 | N4: Type II 포트폴리오 (25.12 기준)
A5: - Type2 세컨클로징 펀드 출자건의 기존 포트폴리오는 펀드 약정일(첫콜 납입 일자) 직전월을 "과거 기준시점"으로 함
A6: ㅇ '26년 6월말을 "최근 기준시점"으로 함 | M6: Type1 감액, 매각기업 | N6: 투자전략팀 별도 확인
A7: - 단, ‘26.6월 전 Deactive 사유*가 발생한 기업은 각 발생 시기 중 빠른 시점의 월말을 최근 기준시점으로 하여 고용인원 수를 집계(단, 감액/폐업기업은 최근 기준시점의 고용인원 0으로 처리) | M7: 폐업기업 | N7: 국세청 사업자등록상태조회
A8: * Deactive 사유 : 패밀리사의 폐업 | 투자에만 해당하는 패밀리사의 감액, 매각 | Type2 펀드의 매각/청산 | M8: 고용인원 | N8: 국민연금 빅데이터 포털-디캠프 계정 통해 데이터 요청/확인
A9: - 단, Deactive 기업이 패밀리사 또는 Type2 투자기업 중 하나로 계속 편입되어 있는 경우에는 '26.6월말 시점 기준의 고용인원 수를 집계 | N9: 더브이씨-스타트업별 고용인원 데이터(국민연금정보 기준)
A10: ㅇ '26년 반기 고용증감 집계시, '25년 까지 Deactive 사유가 발생한 기업은 '26년 연간 고용인원 집계를 할 수 없으므로 과거/최근 기준시점과 무관하게 고용증감을 "N/A"로 표기하여 집계에서 제외 | N10: 크레탑-기업별 종업원현황(국민연금정보 기준)
A11: ※ Type2 포트폴리오 중 스테이지엑스(라구나 스케일업 6호)는 25.12월말 투자 이후 계약 미이행으로 투자 철회되어 포트폴리오 리스트에서 제외됨
A12: ※ 국민연금 조사불가 데이터(오래된 시점의 데이터 등) 는 크레탑, 더브이씨 등재 데이터를 기반으로 기재(조사 불가할 경우 1명으로 기재)
N14: 누적 | O14: 26 반기 | P14: 과거 | Q14: 25년말 | R14: 최근 | S14: Deactive 사유 | Y14: 25.12월 기준 | Z14: 26.6월 기준 | AA14: 패밀리사 누적 | AB14: Type2 누적 | AC14: 패밀리사 '26반기 | AD14: Type2 '26반기 | AE14: 순위용(동점보정) | AF14: 순위용(동점보정) | AG14: 순위용(동점보정) | AH14: 순위용(동점보정)
A15: No | B15: 패밀리사 | C15: 입주 | D15: 투자 | E15: 배치 | F15: 글로벌T1 | G15: Type2 | H15: 투자 | I15: 조사대상 | J15: 사업자등록번호 | K15: 과거 기준시점 | L15: 25년말 시점 | M15: 최근 기준시점 | N15: 고용증감 | O15: 고용증감 | P15: 고용인원 | Q15: 고용인원 | R15: 고용인원 | S15: 발생시점 | T15: 폐업(전체) | U15: 감액(Type1) | V15: 매각(Type1) | W15: 청산/매각(Type2) | X15: 특이사항 | Y15: 고용인원(A') | Z15: 고용인원(B') | AA15: 증감(분석용) | AB15: 증감(분석용) | AC15: 증감(분석용) | AD15: 증감(분석용) | AE15: AA+행번호 | AF15: AB+행번호 | AG15: AC+행번호 | AH15: AD+행번호
A16: 1 | G16: Active | H16: 45464 | I16: (주)코멤텍 | J16: 1018628697 | K16: 45443 | L16: 46022 | M16: 46203 | N16: =R16-P16 -> -4 | O16: =IF(M16<DATE(2026,1,1),"N/A",IF(K16>=DATE(2026,1,1),R16-P16,R16-Q16)) -> -2 | P16: 20 | Q16: 18 | R16: 16 | S16: =IF(OR(LEFT(B16,6)="Active",G16="Active"),"",IF(COUNT(C16,E16,F16)>0,IF(COUNT(T16)=0,"",T16),IF(COUNT(T16:W16)=0,"",MIN(T16:W16)))) | Y16: =IF($M16<DATE(2026,1,1),"",IF($K16>=DATE(2026,1,1),$P16,$Q16)) -> 18 | Z16: =IF($M16<DATE(2026,1,1),"",$R16) -> 16 | AA16: =IF($B16="","",IF(ISNUMBER($N16),$N16,"")) | AB16: =IF($G16="","",IF(ISNUMBER($N16),$N16,"")) -> -4 | AC16: =IF($B16="","",IF(ISNUMBER($O16),$O16,"")) | AD16: =IF($G16="","",IF(ISNUMBER($O16),$O16,"")) -> -2 | AE16: =IF($AA16="","",$AA16+ROW()/1000000) | AF16: =IF($AB16="","",$AB16+ROW()/1000000) -> -3.999984 | AG16: =IF($AC16="","",$AC16+ROW()/1000000) | AH16: =IF($AD16="","",$AD16+ROW()/1000000) -> -1.999984
A17: 2 | G17: Active | H17: 42094 | I17: 버튼테크놀로지 | J17: 1018671758 | K17: 42063 | L17: 46022 | M17: 46203 | N17: =R17-P17 -> -4 | O17: =IF(M17<DATE(2026,1,1),"N/A",IF(K17>=DATE(2026,1,1),R17-P17,R17-Q17)) -> 0 | P17: 4 | Q17: 0 | R17: 0 | S17: =IF(OR(LEFT(B17,6)="Active",G17="Active"),"",IF(COUNT(C17,E17,F17)>0,IF(COUNT(T17)=0,"",T17),IF(COUNT(T17:W17)=0,"",MIN(T17:W17)))) | Y17: =IF($M17<DATE(2026,1,1),"",IF($K17>=DATE(2026,1,1),$P17,$Q17)) -> 0 | Z17: =IF($M17<DATE(2026,1,1),"",$R17) -> 0 | AA17: =IF($B17="","",IF(ISNUMBER($N17),$N17,"")) | AB17: =IF($G17="","",IF(ISNUMBER($N17),$N17,"")) -> -4 | AC17: =IF($B17="","",IF(ISNUMBER($O17),$O17,"")) | AD17: =IF($G17="","",IF(ISNUMBER($O17),$O17,"")) -> 0 | AE17: =IF($AA17="","",$AA17+ROW()/1000000) | AF17: =IF($AB17="","",$AB17+ROW()/1000000) -> -3.999983 | AG17: =IF($AC17="","",$AC17+ROW()/1000000) | AH17: =IF($AD17="","",$AD17+ROW()/1000000) -> 1.7e-05
A18: 3 | G18: 폐업 | H18: 41782 | I18: 500비디오스 | J18: 1018688996 | K18: 41759 | L18: - | M18: 43100 | N18: =R18-P18 -> 0 | O18: =IF(M18<DATE(2026,1,1),"N/A",IF(K18>=DATE(2026,1,1),R18-P18,R18-Q18)) -> N/A | P18: 0 | R18: 0 | S18: =IF(OR(LEFT(B18,6)="Active",G18="Active"),"",IF(COUNT(C18,E18,F18)>0,IF(COUNT(T18)=0,"",T18),IF(COUNT(T18:W18)=0,"",MIN(T18:W18)))) -> 43100 | T18: 43100 | Y18: =IF($M18<DATE(2026,1,1),"",IF($K18>=DATE(2026,1,1),$P18,$Q18)) | Z18: =IF($M18<DATE(2026,1,1),"",$R18) | AA18: =IF($B18="","",IF(ISNUMBER($N18),$N18,"")) | AB18: =IF($G18="","",IF(ISNUMBER($N18),$N18,"")) -> 0 | AC18: =IF($B18="","",IF(ISNUMBER($O18),$O18,"")) | AD18: =IF($G18="","",IF(ISNUMBER($O18),$O18,"")) | AE18: =IF($AA18="","",$AA18+ROW()/1000000) | AF18: =IF($AB18="","",$AB18+ROW()/1000000) -> 1.8e-05 | AG18: =IF($AC18="","",$AC18+ROW()/1000000) | AH18: =IF($AD18="","",$AD18+ROW()/1000000)
A19: 4 | G19: Active | H19: 44523 | I19: (주)널리소프트 | J19: 1018691318 | K19: 44500 | L19: 46022 | M19: 46203 | N19: =R19-P19 -> 11 | O19: =IF(M19<DATE(2026,1,1),"N/A",IF(K19>=DATE(2026,1,1),R19-P19,R19-Q19)) -> -1 | P19: 14 | Q19: 26 | R19: 25 | S19: =IF(OR(LEFT(B19,6)="Active",G19="Active"),"",IF(COUNT(C19,E19,F19)>0,IF(COUNT(T19)=0,"",T19),IF(COUNT(T19:W19)=0,"",MIN(T19:W19)))) | Y19: =IF($M19<DATE(2026,1,1),"",IF($K19>=DATE(2026,1,1),$P19,$Q19)) -> 26 | Z19: =IF($M19<DATE(2026,1,1),"",$R19) -> 25 | AA19: =IF($B19="","",IF(ISNUMBER($N19),$N19,"")) | AB19: =IF($G19="","",IF(ISNUMBER($N19),$N19,"")) -> 11 | AC19: =IF($B19="","",IF(ISNUMBER($O19),$O19,"")) | AD19: =IF($G19="","",IF(ISNUMBER($O19),$O19,"")) -> -1 | AE19: =IF($AA19="","",$AA19+ROW()/1000000) | AF19: =IF($AB19="","",$AB19+ROW()/1000000) -> 11.000019 | AG19: =IF($AC19="","",$AC19+ROW()/1000000) | AH19: =IF($AD19="","",$AD19+ROW()/1000000) -> -0.999981
A20: 5 | B20: Active | C20: 45170 | I20: 다이나메딕(주) | J20: 1028145622 | K20: 45169 | L20: 46022 | M20: 46203 | N20: =R20-P20 -> 6 | O20: =IF(M20<DATE(2026,1,1),"N/A",IF(K20>=DATE(2026,1,1),R20-P20,R20-Q20)) -> 1 | P20: 5 | Q20: 10 | R20: 11 | S20: =IF(OR(LEFT(B20,6)="Active",G20="Active"),"",IF(COUNT(C20,E20,F20)>0,IF(COUNT(T20)=0,"",T20),IF(COUNT(T20:W20)=0,"",MIN(T20:W20)))) | Y20: =IF($M20<DATE(2026,1,1),"",IF($K20>=DATE(2026,1,1),$P20,$Q20)) -> 10 | Z20: =IF($M20<DATE(2026,1,1),"",$R20) -> 11 | AA20: =IF($B20="","",IF(ISNUMBER($N20),$N20,"")) -> 6 | AB20: =IF($G20="","",IF(ISNUMBER($N20),$N20,"")) | AC20: =IF($B20="","",IF(ISNUMBER($O20),$O20,"")) -> 1 | AD20: =IF($G20="","",IF(ISNUMBER($O20),$O20,"")) | AE20: =IF($AA20="","",$AA20+ROW()/1000000) -> 6.00002 | AF20: =IF($AB20="","",$AB20+ROW()/1000000) | AG20: =IF($AC20="","",$AC20+ROW()/1000000) -> 1.00002 | AH20: =IF($AD20="","",$AD20+ROW()/1000000)
A21: 6 | G21: Active | H21: 44757 | I21: (주)탄소중립연구원 | J21: 1028802087 | K21: 44742 | L21: 46022 | M21: 46203 | N21: =R21-P21 -> 8 | O21: =IF(M21<DATE(2026,1,1),"N/A",IF(K21>=DATE(2026,1,1),R21-P21,R21-Q21)) -> 3 | P21: 5 | Q21: 10 | R21: 13 | S21: =IF(OR(LEFT(B21,6)="Active",G21="Active"),"",IF(COUNT(C21,E21,F21)>0,IF(COUNT(T21)=0,"",T21),IF(COUNT(T21:W21)=0,"",MIN(T21:W21)))) | Y21: =IF($M21<DATE(2026,1,1),"",IF($K21>=DATE(2026,1,1),$P21,$Q21)) -> 10 | Z21: =IF($M21<DATE(2026,1,1),"",$R21) -> 13 | AA21: =IF($B21="","",IF(ISNUMBER($N21),$N21,"")) | AB21: =IF($G21="","",IF(ISNUMBER($N21),$N21,"")) -> 8 | AC21: =IF($B21="","",IF(ISNUMBER($O21),$O21,"")) | AD21: =IF($G21="","",IF(ISNUMBER($O21),$O21,"")) -> 3 | AE21: =IF($AA21="","",$AA21+ROW()/1000000) | AF21: =IF($AB21="","",$AB21+ROW()/1000000) -> 8.000021 | AG21: =IF($AC21="","",$AC21+ROW()/1000000) | AH21: =IF($AD21="","",$AD21+ROW()/1000000) -> 3.000021
A22: 7 | G22: Active | H22: 45412 | I22: (주)스피드플로어 | J22: 1038702332 | K22: 45382 | L22: 46022 | M22: 46203 | N22: =R22-P22 -> 5 | O22: =IF(M22<DATE(2026,1,1),"N/A",IF(K22>=DATE(2026,1,1),R22-P22,R22-Q22)) -> 1 | P22: 9 | Q22: 13 | R22: 14 | S22: =IF(OR(LEFT(B22,6)="Active",G22="Active"),"",IF(COUNT(C22,E22,F22)>0,IF(COUNT(T22)=0,"",T22),IF(COUNT(T22:W22)=0,"",MIN(T22:W22)))) | Y22: =IF($M22<DATE(2026,1,1),"",IF($K22>=DATE(2026,1,1),$P22,$Q22)) -> 13 | Z22: =IF($M22<DATE(2026,1,1),"",$R22) -> 14 | AA22: =IF($B22="","",IF(ISNUMBER($N22),$N22,"")) | AB22: =IF($G22="","",IF(ISNUMBER($N22),$N22,"")) -> 5 | AC22: =IF($B22="","",IF(ISNUMBER($O22),$O22,"")) | AD22: =IF($G22="","",IF(ISNUMBER($O22),$O22,"")) -> 1 | AE22: =IF($AA22="","",$AA22+ROW()/1000000) | AF22: =IF($AB22="","",$AB22+ROW()/1000000) -> 5.000022 | AG22: =IF($AC22="","",$AC22+ROW()/1000000) | AH22: =IF($AD22="","",$AD22+ROW()/1000000) -> 1.000022
A23: 8 | G23: Active | H23: 42846 | I23: (주)스튜디오8 | J23: 1048162461 | K23: 42825 | L23: 46022 | M23: 46203 | N23: =R23-P23 -> -130 | O23: =IF(M23<DATE(2026,1,1),"N/A",IF(K23>=DATE(2026,1,1),R23-P23,R23-Q23)) -> 0 | P23: 130 | Q23: 0 | R23: 0 | S23: =IF(OR(LEFT(B23,6)="Active",G23="Active"),"",IF(COUNT(C23,E23,F23)>0,IF(COUNT(T23)=0,"",T23),IF(COUNT(T23:W23)=0,"",MIN(T23:W23)))) | Y23: =IF($M23<DATE(2026,1,1),"",IF($K23>=DATE(2026,1,1),$P23,$Q23)) -> 0 | Z23: =IF($M23<DATE(2026,1,1),"",$R23) -> 0 | AA23: =IF($B23="","",IF(ISNUMBER($N23),$N23,"")) | AB23: =IF($G23="","",IF(ISNUMBER($N23),$N23,"")) -> -130 | AC23: =IF($B23="","",IF(ISNUMBER($O23),$O23,"")) | AD23: =IF($G23="","",IF(ISNUMBER($O23),$O23,"")) -> 0 | AE23: =IF($AA23="","",$AA23+ROW()/1000000) | AF23: =IF($AB23="","",$AB23+ROW()/1000000) -> -129.99998 | AG23: =IF($AC23="","",$AC23+ROW()/1000000) | AH23: =IF($AD23="","",$AD23+ROW()/1000000) -> 2.3e-05
A24: 9 | G24: 폐업 | H24: 41746 | I24: 소개요 | J24: 1048613645 | K24: 41729 | L24: - | M24: 42490 | N24: =R24-P24 -> -1 | O24: =IF(M24<DATE(2026,1,1),"N/A",IF(K24>=DATE(2026,1,1),R24-P24,R24-Q24)) -> N/A | P24: 1 | R24: 0 | S24: =IF(OR(LEFT(B24,6)="Active",G24="Active"),"",IF(COUNT(C24,E24,F24)>0,IF(COUNT(T24)=0,"",T24),IF(COUNT(T24:W24)=0,"",MIN(T24:W24)))) -> 42478 | T24: 42478 | Y24: =IF($M24<DATE(2026,1,1),"",IF($K24>=DATE(2026,1,1),$P24,$Q24)) | Z24: =IF($M24<DATE(2026,1,1),"",$R24) | AA24: =IF($B24="","",IF(ISNUMBER($N24),$N24,"")) | AB24: =IF($G24="","",IF(ISNUMBER($N24),$N24,"")) -> -1 | AC24: =IF($B24="","",IF(ISNUMBER($O24),$O24,"")) | AD24: =IF($G24="","",IF(ISNUMBER($O24),$O24,"")) | AE24: =IF($AA24="","",$AA24+ROW()/1000000) | AF24: =IF($AB24="","",$AB24+ROW()/1000000) -> -0.999976 | AG24: =IF($AC24="","",$AC24+ROW()/1000000) | AH24: =IF($AD24="","",$AD24+ROW()/1000000)
A25: 10 | G25: 폐업 | H25: 43461 | I25: ShuShu Cosmetic | J25: 1048651329 | K25: 43434 | L25: - | M25: 44530 | N25: =R25-P25 -> -18 | O25: =IF(M25<DATE(2026,1,1),"N/A",IF(K25>=DATE(2026,1,1),R25-P25,R25-Q25)) -> N/A | P25: 18 | R25: 0 | S25: =IF(OR(LEFT(B25,6)="Active",G25="Active"),"",IF(COUNT(C25,E25,F25)>0,IF(COUNT(T25)=0,"",T25),IF(COUNT(T25:W25)=0,"",MIN(T25:W25)))) -> 44519 | T25: 44519 | W25: 45721 | Y25: =IF($M25<DATE(2026,1,1),"",IF($K25>=DATE(2026,1,1),$P25,$Q25)) | Z25: =IF($M25<DATE(2026,1,1),"",$R25) | AA25: =IF($B25="","",IF(ISNUMBER($N25),$N25,"")) | AB25: =IF($G25="","",IF(ISNUMBER($N25),$N25,"")) -> -18 | AC25: =IF($B25="","",IF(ISNUMBER($O25),$O25,"")) | AD25: =IF($G25="","",IF(ISNUMBER($O25),$O25,"")) | AE25: =IF($AA25="","",$AA25+ROW()/1000000) | AF25: =IF($AB25="","",$AB25+ROW()/1000000) -> -17.999975 | AG25: =IF($AC25="","",$AC25+ROW()/1000000) | AH25: =IF($AD25="","",$AD25+ROW()/1000000)
A26: 11 | G26: Active | H26: 43276 | I26: 글로벌텍스프리(주) | J26: 1048656135 | K26: 43251 | L26: 46022 | M26: 46203 | N26: =R26-P26 -> 6 | O26: =IF(M26<DATE(2026,1,1),"N/A",IF(K26>=DATE(2026,1,1),R26-P26,R26-Q26)) -> 3 | P26: 145 | Q26: 148 | R26: 151 | S26: =IF(OR(LEFT(B26,6)="Active",G26="Active"),"",IF(COUNT(C26,E26,F26)>0,IF(COUNT(T26)=0,"",T26),IF(COUNT(T26:W26)=0,"",MIN(T26:W26)))) | Y26: =IF($M26<DATE(2026,1,1),"",IF($K26>=DATE(2026,1,1),$P26,$Q26)) -> 148 | Z26: =IF($M26<DATE(2026,1,1),"",$R26) -> 151 | AA26: =IF($B26="","",IF(ISNUMBER($N26),$N26,"")) | AB26: =IF($G26="","",IF(ISNUMBER($N26),$N26,"")) -> 6 | AC26: =IF($B26="","",IF(ISNUMBER($O26),$O26,"")) | AD26: =IF($G26="","",IF(ISNUMBER($O26),$O26,"")) -> 3 | AE26: =IF($AA26="","",$AA26+ROW()/1000000) | AF26: =IF($AB26="","",$AB26+ROW()/1000000) -> 6.000026 | AG26: =IF($AC26="","",$AC26+ROW()/1000000) | AH26: =IF($AD26="","",$AD26+ROW()/1000000) -> 3.000026
A27: 12 | G27: 청산/매각 | H27: 43522 | I27: 프로젝트노아 | J27: 1048656251 | K27: 43496 | L27: - | M27: 45747 | N27: =R27-P27 -> -5 | O27: =IF(M27<DATE(2026,1,1),"N/A",IF(K27>=DATE(2026,1,1),R27-P27,R27-Q27)) -> N/A | P27: 10 | R27: 5 | S27: =IF(OR(LEFT(B27,6)="Active",G27="Active"),"",IF(COUNT(C27,E27,F27)>0,IF(COUNT(T27)=0,"",T27),IF(COUNT(T27:W27)=0,"",MIN(T27:W27)))) -> 45721 | W27: 45721 | Y27: =IF($M27<DATE(2026,1,1),"",IF($K27>=DATE(2026,1,1),$P27,$Q27)) | Z27: =IF($M27<DATE(2026,1,1),"",$R27) | AA27: =IF($B27="","",IF(ISNUMBER($N27),$N27,"")) | AB27: =IF($G27="","",IF(ISNUMBER($N27),$N27,"")) -> -5 | AC27: =IF($B27="","",IF(ISNUMBER($O27),$O27,"")) | AD27: =IF($G27="","",IF(ISNUMBER($O27),$O27,"")) | AE27: =IF($AA27="","",$AA27+ROW()/1000000) | AF27: =IF($AB27="","",$AB27+ROW()/1000000) -> -4.999973 | AG27: =IF($AC27="","",$AC27+ROW()/1000000) | AH27: =IF($AD27="","",$AD27+ROW()/1000000)
A28: 13 | G28: Active | H28: 44061 | I28: (주)스파이더랩 | J28: 1048660468 | K28: 44043 | L28: 46022 | M28: 46203 | N28: =R28-P28 -> 15 | O28: =IF(M28<DATE(2026,1,1),"N/A",IF(K28>=DATE(2026,1,1),R28-P28,R28-Q28)) -> 3 | P28: 6 | Q28: 18 | R28: 21 | S28: =IF(OR(LEFT(B28,6)="Active",G28="Active"),"",IF(COUNT(C28,E28,F28)>0,IF(COUNT(T28)=0,"",T28),IF(COUNT(T28:W28)=0,"",MIN(T28:W28)))) | Y28: =IF($M28<DATE(2026,1,1),"",IF($K28>=DATE(2026,1,1),$P28,$Q28)) -> 18 | Z28: =IF($M28<DATE(2026,1,1),"",$R28) -> 21 | AA28: =IF($B28="","",IF(ISNUMBER($N28),$N28,"")) | AB28: =IF($G28="","",IF(ISNUMBER($N28),$N28,"")) -> 15 | AC28: =IF($B28="","",IF(ISNUMBER($O28),$O28,"")) | AD28: =IF($G28="","",IF(ISNUMBER($O28),$O28,"")) -> 3 | AE28: =IF($AA28="","",$AA28+ROW()/1000000) | AF28: =IF($AB28="","",$AB28+ROW()/1000000) -> 15.000028 | AG28: =IF($AC28="","",$AC28+ROW()/1000000) | AH28: =IF($AD28="","",$AD28+ROW()/1000000) -> 3.000028
A29: 14 | G29: Active | H29: 45617 | I29: 케이투레이저시스템 | J29: 1058671842 | K29: 45596 | L29: 46022 | M29: 46203 | N29: =R29-P29 -> 10 | O29: =IF(M29<DATE(2026,1,1),"N/A",IF(K29>=DATE(2026,1,1),R29-P29,R29-Q29)) -> 7 | P29: 49 | Q29: 52 | R29: 59 | S29: =IF(OR(LEFT(B29,6)="Active",G29="Active"),"",IF(COUNT(C29,E29,F29)>0,IF(COUNT(T29)=0,"",T29),IF(COUNT(T29:W29)=0,"",MIN(T29:W29)))) | Y29: =IF($M29<DATE(2026,1,1),"",IF($K29>=DATE(2026,1,1),$P29,$Q29)) -> 52 | Z29: =IF($M29<DATE(2026,1,1),"",$R29) -> 59 | AA29: =IF($B29="","",IF(ISNUMBER($N29),$N29,"")) | AB29: =IF($G29="","",IF(ISNUMBER($N29),$N29,"")) -> 10 | AC29: =IF($B29="","",IF(ISNUMBER($O29),$O29,"")) | AD29: =IF($G29="","",IF(ISNUMBER($O29),$O29,"")) -> 7 | AE29: =IF($AA29="","",$AA29+ROW()/1000000) | AF29: =IF($AB29="","",$AB29+ROW()/1000000) -> 10.000029 | AG29: =IF($AC29="","",$AC29+ROW()/1000000) | AH29: =IF($AD29="","",$AD29+ROW()/1000000) -> 7.000029
A30: 15 | G30: Active | H30: 44057 | I30: (주)뉴젠솔루션 | J30: 1058751159 | K30: 44043 | L30: 46022 | M30: 46203 | N30: =R30-P30 -> 6 | O30: =IF(M30<DATE(2026,1,1),"N/A",IF(K30>=DATE(2026,1,1),R30-P30,R30-Q30)) -> 14 | P30: 72 | Q30: 64 | R30: 78 | S30: =IF(OR(LEFT(B30,6)="Active",G30="Active"),"",IF(COUNT(C30,E30,F30)>0,IF(COUNT(T30)=0,"",T30),IF(COUNT(T30:W30)=0,"",MIN(T30:W30)))) | Y30: =IF($M30<DATE(2026,1,1),"",IF($K30>=DATE(2026,1,1),$P30,$Q30)) -> 64 | Z30: =IF($M30<DATE(2026,1,1),"",$R30) -> 78 | AA30: =IF($B30="","",IF(ISNUMBER($N30),$N30,"")) | AB30: =IF($G30="","",IF(ISNUMBER($N30),$N30,"")) -> 6 | AC30: =IF($B30="","",IF(ISNUMBER($O30),$O30,"")) | AD30: =IF($G30="","",IF(ISNUMBER($O30),$O30,"")) -> 14 | AE30: =IF($AA30="","",$AA30+ROW()/1000000) | AF30: =IF($AB30="","",$AB30+ROW()/1000000) -> 6.00003 | AG30: =IF($AC30="","",$AC30+ROW()/1000000) | AH30: =IF($AD30="","",$AD30+ROW()/1000000) -> 14.00003
A31: 16 | G31: 폐업 | H31: 42661 | I31: 텀블벅 | J31: 1058752823 | K31: 42643 | L31: - | M31: 45138 | N31: =R31-P31 -> -16 | O31: =IF(M31<DATE(2026,1,1),"N/A",IF(K31>=DATE(2026,1,1),R31-P31,R31-Q31)) -> N/A | P31: 16 | R31: 0 | S31: =IF(OR(LEFT(B31,6)="Active",G31="Active"),"",IF(COUNT(C31,E31,F31)>0,IF(COUNT(T31)=0,"",T31),IF(COUNT(T31:W31)=0,"",MIN(T31:W31)))) -> 45114 | T31: 45114 | Y31: =IF($M31<DATE(2026,1,1),"",IF($K31>=DATE(2026,1,1),$P31,$Q31)) | Z31: =IF($M31<DATE(2026,1,1),"",$R31) | AA31: =IF($B31="","",IF(ISNUMBER($N31),$N31,"")) | AB31: =IF($G31="","",IF(ISNUMBER($N31),$N31,"")) -> -16 | AC31: =IF($B31="","",IF(ISNUMBER($O31),$O31,"")) | AD31: =IF($G31="","",IF(ISNUMBER($O31),$O31,"")) | AE31: =IF($AA31="","",$AA31+ROW()/1000000) | AF31: =IF($AB31="","",$AB31+ROW()/1000000) -> -15.999969 | AG31: =IF($AC31="","",$AC31+ROW()/1000000) | AH31: =IF($AD31="","",$AD31+ROW()/1000000)
A32: 17 | G32: Active | H32: 44295 | I32: (주)헬스허브 | J32: 1058768397 | K32: 44286 | L32: 46022 | M32: 46203 | N32: =R32-P32 -> -35 | O32: =IF(M32<DATE(2026,1,1),"N/A",IF(K32>=DATE(2026,1,1),R32-P32,R32-Q32)) -> -22 | P32: 63 | Q32: 50 | R32: 28 | S32: =IF(OR(LEFT(B32,6)="Active",G32="Active"),"",IF(COUNT(C32,E32,F32)>0,IF(COUNT(T32)=0,"",T32),IF(COUNT(T32:W32)=0,"",MIN(T32:W32)))) | Y32: =IF($M32<DATE(2026,1,1),"",IF($K32>=DATE(2026,1,1),$P32,$Q32)) -> 50 | Z32: =IF($M32<DATE(2026,1,1),"",$R32) -> 28 | AA32: =IF($B32="","",IF(ISNUMBER($N32),$N32,"")) | AB32: =IF($G32="","",IF(ISNUMBER($N32),$N32,"")) -> -35 | AC32: =IF($B32="","",IF(ISNUMBER($O32),$O32,"")) | AD32: =IF($G32="","",IF(ISNUMBER($O32),$O32,"")) -> -22 | AE32: =IF($AA32="","",$AA32+ROW()/1000000) | AF32: =IF($AB32="","",$AB32+ROW()/1000000) -> -34.999968 | AG32: =IF($AC32="","",$AC32+ROW()/1000000) | AH32: =IF($AD32="","",$AD32+ROW()/1000000) -> -21.999968
A33: 18 | G33: Active | H33: 42024 | I33: 다비오 | J33: 1058768437 | K33: 42004 | L33: 46022 | M33: 46203 | N33: =R33-P33 -> 79 | O33: =IF(M33<DATE(2026,1,1),"N/A",IF(K33>=DATE(2026,1,1),R33-P33,R33-Q33)) -> 8 | P33: 10 | Q33: 81 | R33: 89 | S33: =IF(OR(LEFT(B33,6)="Active",G33="Active"),"",IF(COUNT(C33,E33,F33)>0,IF(COUNT(T33)=0,"",T33),IF(COUNT(T33:W33)=0,"",MIN(T33:W33)))) | Y33: =IF($M33<DATE(2026,1,1),"",IF($K33>=DATE(2026,1,1),$P33,$Q33)) -> 81 | Z33: =IF($M33<DATE(2026,1,1),"",$R33) -> 89 | AA33: =IF($B33="","",IF(ISNUMBER($N33),$N33,"")) | AB33: =IF($G33="","",IF(ISNUMBER($N33),$N33,"")) -> 79 | AC33: =IF($B33="","",IF(ISNUMBER($O33),$O33,"")) | AD33: =IF($G33="","",IF(ISNUMBER($O33),$O33,"")) -> 8 | AE33: =IF($AA33="","",$AA33+ROW()/1000000) | AF33: =IF($AB33="","",$AB33+ROW()/1000000) -> 79.000033 | AG33: =IF($AC33="","",$AC33+ROW()/1000000) | AH33: =IF($AD33="","",$AD33+ROW()/1000000) -> 8.000033
A34: 19 | G34: Active | H34: 42594 | I34: 엠버스 | J34: 1058773094 | K34: 42582 | L34: 46022 | M34: 46203 | N34: =R34-P34 -> -12 | O34: =IF(M34<DATE(2026,1,1),"N/A",IF(K34>=DATE(2026,1,1),R34-P34,R34-Q34)) -> 0 | P34: 12 | Q34: 0 | R34: 0 | S34: =IF(OR(LEFT(B34,6)="Active",G34="Active"),"",IF(COUNT(C34,E34,F34)>0,IF(COUNT(T34)=0,"",T34),IF(COUNT(T34:W34)=0,"",MIN(T34:W34)))) | Y34: =IF($M34<DATE(2026,1,1),"",IF($K34>=DATE(2026,1,1),$P34,$Q34)) -> 0 | Z34: =IF($M34<DATE(2026,1,1),"",$R34) -> 0 | AA34: =IF($B34="","",IF(ISNUMBER($N34),$N34,"")) | AB34: =IF($G34="","",IF(ISNUMBER($N34),$N34,"")) -> -12 | AC34: =IF($B34="","",IF(ISNUMBER($O34),$O34,"")) | AD34: =IF($G34="","",IF(ISNUMBER($O34),$O34,"")) -> 0 | AE34: =IF($AA34="","",$AA34+ROW()/1000000) | AF34: =IF($AB34="","",$AB34+ROW()/1000000) -> -11.999966 | AG34: =IF($AC34="","",$AC34+ROW()/1000000) | AH34: =IF($AD34="","",$AD34+ROW()/1000000) -> 3.4e-05
A35: 20 | G35: Active | H35: 43383 | I35: (주)뱅크샐러드 | J35: 1058773978 | K35: 43373 | L35: 46022 | M35: 46203 | N35: =R35-P35 -> 101 | O35: =IF(M35<DATE(2026,1,1),"N/A",IF(K35>=DATE(2026,1,1),R35-P35,R35-Q35)) -> 10 | P35: 58 | Q35: 149 | R35: 159 | S35: =IF(OR(LEFT(B35,6)="Active",G35="Active"),"",IF(COUNT(C35,E35,F35)>0,IF(COUNT(T35)=0,"",T35),IF(COUNT(T35:W35)=0,"",MIN(T35:W35)))) | Y35: =IF($M35<DATE(2026,1,1),"",IF($K35>=DATE(2026,1,1),$P35,$Q35)) -> 149 | Z35: =IF($M35<DATE(2026,1,1),"",$R35) -> 159 | AA35: =IF($B35="","",IF(ISNUMBER($N35),$N35,"")) | AB35: =IF($G35="","",IF(ISNUMBER($N35),$N35,"")) -> 101 | AC35: =IF($B35="","",IF(ISNUMBER($O35),$O35,"")) | AD35: =IF($G35="","",IF(ISNUMBER($O35),$O35,"")) -> 10 | AE35: =IF($AA35="","",$AA35+ROW()/1000000) | AF35: =IF($AB35="","",$AB35+ROW()/1000000) -> 101.00003 | AG35: =IF($AC35="","",$AC35+ROW()/1000000) | AH35: =IF($AD35="","",$AD35+ROW()/1000000) -> 10.000035
A36: 21 | G36: Active | H36: 45730 | I36: 캐플릭스 | J36: 1058776000 | K36: 45716 | L36: 46022 | M36: 46203 | N36: =R36-P36 -> 1 | O36: =IF(M36<DATE(2026,1,1),"N/A",IF(K36>=DATE(2026,1,1),R36-P36,R36-Q36)) -> 5 | P36: 31 | Q36: 27 | R36: 32 | S36: =IF(OR(LEFT(B36,6)="Active",G36="Active"),"",IF(COUNT(C36,E36,F36)>0,IF(COUNT(T36)=0,"",T36),IF(COUNT(T36:W36)=0,"",MIN(T36:W36)))) | Y36: =IF($M36<DATE(2026,1,1),"",IF($K36>=DATE(2026,1,1),$P36,$Q36)) -> 27 | Z36: =IF($M36<DATE(2026,1,1),"",$R36) -> 32 | AA36: =IF($B36="","",IF(ISNUMBER($N36),$N36,"")) | AB36: =IF($G36="","",IF(ISNUMBER($N36),$N36,"")) -> 1 | AC36: =IF($B36="","",IF(ISNUMBER($O36),$O36,"")) | AD36: =IF($G36="","",IF(ISNUMBER($O36),$O36,"")) -> 5 | AE36: =IF($AA36="","",$AA36+ROW()/1000000) | AF36: =IF($AB36="","",$AB36+ROW()/1000000) -> 1.000036 | AG36: =IF($AC36="","",$AC36+ROW()/1000000) | AH36: =IF($AD36="","",$AD36+ROW()/1000000) -> 5.000036
A37: 22 | B37: 폐업 | C37: 43437 | D37: 43458 | I37: 컨트롤클로더 | J37: 1058795915 | K37: 43434 | L37: - | M37: 44926 | N37: =R37-P37 -> -3 | O37: =IF(M37<DATE(2026,1,1),"N/A",IF(K37>=DATE(2026,1,1),R37-P37,R37-Q37)) -> N/A | P37: 3 | R37: 0 | S37: =IF(OR(LEFT(B37,6)="Active",G37="Active"),"",IF(COUNT(C37,E37,F37)>0,IF(COUNT(T37)=0,"",T37),IF(COUNT(T37:W37)=0,"",MIN(T37:W37)))) -> 44926 | T37: 44926 | U37: 45291 | V37: 45560 | Y37: =IF($M37<DATE(2026,1,1),"",IF($K37>=DATE(2026,1,1),$P37,$Q37)) | Z37: =IF($M37<DATE(2026,1,1),"",$R37) | AA37: =IF($B37="","",IF(ISNUMBER($N37),$N37,"")) -> -3 | AB37: =IF($G37="","",IF(ISNUMBER($N37),$N37,"")) | AC37: =IF($B37="","",IF(ISNUMBER($O37),$O37,"")) | AD37: =IF($G37="","",IF(ISNUMBER($O37),$O37,"")) | AE37: =IF($AA37="","",$AA37+ROW()/1000000) -> -2.999963 | AF37: =IF($AB37="","",$AB37+ROW()/1000000) | AG37: =IF($AC37="","",$AC37+ROW()/1000000) | AH37: =IF($AD37="","",$AD37+ROW()/1000000)
A38: 23 | B38: Active(입주) | C38: 45484 | D38: 42916 | I38: 주식회사후즈굿 | J38: 1058802387 | K38: 42886 | L38: 46022 | M38: 46203 | N38: =R38-P38 -> -6 | O38: =IF(M38<DATE(2026,1,1),"N/A",IF(K38>=DATE(2026,1,1),R38-P38,R38-Q38)) -> -1 | P38: 7 | Q38: 2 | R38: 1 | S38: =IF(OR(LEFT(B38,6)="Active",G38="Active"),"",IF(COUNT(C38,E38,F38)>0,IF(COUNT(T38)=0,"",T38),IF(COUNT(T38:W38)=0,"",MIN(T38:W38)))) | U38: 45657 | V38: 45922 | X38: 감액/매각된 입주 패밀리사 | Y38: =IF($M38<DATE(2026,1,1),"",IF($K38>=DATE(2026,1,1),$P38,$Q38)) -> 2 | Z38: =IF($M38<DATE(2026,1,1),"",$R38) -> 1 | AA38: =IF($B38="","",IF(ISNUMBER($N38),$N38,"")) -> -6 | AB38: =IF($G38="","",IF(ISNUMBER($N38),$N38,"")) | AC38: =IF($B38="","",IF(ISNUMBER($O38),$O38,"")) -> -1 | AD38: =IF($G38="","",IF(ISNUMBER($O38),$O38,"")) | AE38: =IF($AA38="","",$AA38+ROW()/1000000) -> -5.999962 | AF38: =IF($AB38="","",$AB38+ROW()/1000000) | AG38: =IF($AC38="","",$AC38+ROW()/1000000) -> -0.999962 | AH38: =IF($AD38="","",$AD38+ROW()/1000000)
A39: 24 | G39: 폐업 | H39: 42319 | I39: (주)직토 | J39: 1058802413 | K39: 42308 | L39: - | M39: 44561 | N39: =R39-P39 -> -15 | O39: =IF(M39<DATE(2026,1,1),"N/A",IF(K39>=DATE(2026,1,1),R39-P39,R39-Q39)) -> N/A | P39: 15 | R39: 0 | S39: =IF(OR(LEFT(B39,6)="Active",G39="Active"),"",IF(COUNT(C39,E39,F39)>0,IF(COUNT(T39)=0,"",T39),IF(COUNT(T39:W39)=0,"",MIN(T39:W39)))) -> 44561 | T39: 44561 | Y39: =IF($M39<DATE(2026,1,1),"",IF($K39>=DATE(2026,1,1),$P39,$Q39)) | Z39: =IF($M39<DATE(2026,1,1),"",$R39) | AA39: =IF($B39="","",IF(ISNUMBER($N39),$N39,"")) | AB39: =IF($G39="","",IF(ISNUMBER($N39),$N39,"")) -> -15 | AC39: =IF($B39="","",IF(ISNUMBER($O39),$O39,"")) | AD39: =IF($G39="","",IF(ISNUMBER($O39),$O39,"")) | AE39: =IF($AA39="","",$AA39+ROW()/1000000) | AF39: =IF($AB39="","",$AB39+ROW()/1000000) -> -14.999961 | AG39: =IF($AC39="","",$AC39+ROW()/1000000) | AH39: =IF($AD39="","",$AD39+ROW()/1000000)
A40: 25 | G40: Active | H40: 41828 | I40: 캠스콘 | J40: 1058804880 | K40: 41820 | L40: 46022 | M40: 46203 | N40: =R40-P40 -> 1 | O40: =IF(M40<DATE(2026,1,1),"N/A",IF(K40>=DATE(2026,1,1),R40-P40,R40-Q40)) -> 0 | P40: 0 | Q40: 1 | R40: 1 | S40: =IF(OR(LEFT(B40,6)="Active",G40="Active"),"",IF(COUNT(C40,E40,F40)>0,IF(COUNT(T40)=0,"",T40),IF(COUNT(T40:W40)=0,"",MIN(T40:W40)))) | Y40: =IF($M40<DATE(2026,1,1),"",IF($K40>=DATE(2026,1,1),$P40,$Q40)) -> 1 | Z40: =IF($M40<DATE(2026,1,1),"",$R40) -> 1 | AA40: =IF($B40="","",IF(ISNUMBER($N40),$N40,"")) | AB40: =IF($G40="","",IF(ISNUMBER($N40),$N40,"")) -> 1 | AC40: =IF($B40="","",IF(ISNUMBER($O40),$O40,"")) | AD40: =IF($G40="","",IF(ISNUMBER($O40),$O40,"")) -> 0 | AE40: =IF($AA40="","",$AA40+ROW()/1000000) | AF40: =IF($AB40="","",$AB40+ROW()/1000000) -> 1.00004 | AG40: =IF($AC40="","",$AC40+ROW()/1000000) | AH40: =IF($AD40="","",$AD40+ROW()/1000000) -> 4e-05
A41: 26 | G41: Active | H41: 44823 | I41: 하이리움산업(주) | J41: 1058806971 | K41: 44804 | L41: 46022 | M41: 46203 | N41: =R41-P41 -> 2 | O41: =IF(M41<DATE(2026,1,1),"N/A",IF(K41>=DATE(2026,1,1),R41-P41,R41-Q41)) -> -10 | P41: 62 | Q41: 74 | R41: 64 | S41: =IF(OR(LEFT(B41,6)="Active",G41="Active"),"",IF(COUNT(C41,E41,F41)>0,IF(COUNT(T41)=0,"",T41),IF(COUNT(T41:W41)=0,"",MIN(T41:W41)))) | Y41: =IF($M41<DATE(2026,1,1),"",IF($K41>=DATE(2026,1,1),$P41,$Q41)) -> 74 | Z41: =IF($M41<DATE(2026,1,1),"",$R41) -> 64 | AA41: =IF($B41="","",IF(ISNUMBER($N41),$N41,"")) | AB41: =IF($G41="","",IF(ISNUMBER($N41),$N41,"")) -> 2 | AC41: =IF($B41="","",IF(ISNUMBER($O41),$O41,"")) | AD41: =IF($G41="","",IF(ISNUMBER($O41),$O41,"")) -> -10 | AE41: =IF($AA41="","",$AA41+ROW()/1000000) | AF41: =IF($AB41="","",$AB41+ROW()/1000000) -> 2.000041 | AG41: =IF($AC41="","",$AC41+ROW()/1000000) | AH41: =IF($AD41="","",$AD41+ROW()/1000000) -> -9.999959
...

Sheet 검색불가(336개사_26년 6월)
A1: 검색불가 기업('26년 6월 기준 실적에서 제외)
A4: No | B4: 패밀리사 | C4: 입주 | D4: 투자 | E4: 배치 | F4: 글로벌T1 | G4: Type2 | H4: 투자 | I4: 펀드명 | J4: 사업자등록번호 | K4: 사업장명
A5: 1 | B5: 폐업 | C5: 44896 | J5: n/a | K5: COOLMINT
A6: 2 | B6: Active(입주) | C6: 42705 | J6: n/a | K6: 겟링크스
A7: 3 | B7: 폐업 | C7: 42767 | J7: n/a | K7: 디씨엑스코리아
A8: 4 | B8: 폐업 | C8: 42552 | J8: n/a | K8: 목장커머스
A9: 5 | B9: 미상 | C9: 44896 | D9: 44923 | J9: 2950473 | K9: 무토월드
A10: 6 | B10: Active | F10: 46122 | J10: 365163347 | K10: Provally Inc.
A11: 7 | C11: 46023 | G11: Type2 | H11: 45904 | I11: Krew Capital Venture Fund I | J11: 393956729 | K11: Director Labs, Inc.
A12: 8 | G12: Type2 | H12: 45992 | I12: Shinhan-GB FutureFlow Fund | J12: 해외 | K12: 12 pharmacy
A13: 9 | G13: Type2 | H13: 45604 | I13: 스프링캠프-KIF 초기전문 투자조합 | J13: 해외 | K13: 1849 Bio Inc
A14: 10 | G14: Type2 | H14: 42867 | I14: 카카오 디지털콘텐츠 펀드 | J14: Bib-do-00011 | K14: 51GIF
A15: 11 | G15: Type2 | H15: 43761 | I15: Strong Seed Fund II, L.P. | J15: 해외 | K15: 7till8
A16: 12 | G16: Type2 | H16: 42234 | I16: Strong Seed Fund II, L.P. | J16: 해외 | K16: 8omakase
A17: 13 | G17: Type2 | H17: 42755 | I17: Adval-CCVC DC 창업초기 투자조합 | J17: 111-11-11111 | K17: A DRBRAND PTE. LTD.
A18: 14 | G18: Type2 | H18: 45166 | I18: 임팩트 피크닉 투자조합 | J18: SG1-00-00201 | K18: AIRCITY GLOBAL PTE. LTD.
A19: 15 | G19: Type2 | H19: 42790 | I19: 카카오 디지털콘텐츠 펀드 | J19: Bkc-ub-00010 | K19: ALCACRUZ INC
A20: 16 | G20: Type2 | H20: 45436 | I20: 스마일게이트로켓부스터3호, 더벤처스 파운더스 커뮤니티 펀드 1 | J20: 해외 | K20: ALLSALE Corp.
A21: 17 | G21: Type2 | H21: 45821 | I21: 500 Global Flagship VI, L.P. | J21: 해외 | K21: ALORE AI INC
A22: 18 | G22: Type2 | H22: 45918 | I22: 스타트업코리아 카카오 코파일럿 펀드 | J22: 해외 | K22: APOLLO STUDIO PTE LTD
A23: 19 | G23: Type2 | H23: 45627 | I23: Golden Gate Ventures Fund IV | J23: 해외 | K23: AWE
... A335: 331 | G335: Type2 | H335: 44650 | I335: KDBC-FP 테크넥스트 투자조합 1호 | J335: 998-49-84890 | K335: PLANETARIUM LABS PTE. LTD.
A336: 332 | G336: Type2 | H336: 45981 | I336: 베이스업템포벤처투자조합 | J336: 3128059968 | K336: 베이스아누아뷰티벤처조합
A337: 333 | G337: Type2 | H337: 45482 | I337: Strong Ventures V, L.P. | J337: 5568602227 | K337: 귤메달 | W337: 잘못된 사업자번호
A338: 334 | G338: Type2 | H338: 43220 | I338: Strong Seed Fund II, L.P. | J338: 3748000937 | K338: 프라이머 시즌5
A339: 335 | G339: Type2 | H339: 42248 | I339: Strong Seed Fund II, L.P. | J339: 5058700184 | K339: 프라이머 시즌4
A340: 336 | G340: Type2 | H340: 43277 | I340: Strong Seed Fund II, L.P. | J340: 7718000953 | K340: 프라이머 프로라타1호
